[2024-06-24 20:16:30,960: INFO: main: Welcome to our custom log]
[2024-06-25 17:55:12,708: INFO: main: >>>> stageData Ingestion Stage started<<<]
[2024-06-25 17:55:12,708: INFO: common: yaml file: config\config.yaml loaded successfully]
[2024-06-25 17:55:12,708: INFO: common: yaml file: params.yaml loaded successfully]
[2024-06-25 17:55:12,708: ERROR: main: yaml file is empty]
Traceback (most recent call last):
  File "d:\text_summarizer\src\Text_Summarizer\utils\common.py", line 29, in read_yaml
    return ConfigBox(content)
  File "box\box.py", line 259, in box.box.Box.__init__
box.exceptions.BoxValueError: First argument must be mapping or iterable

During handling of the above exception, another exception occurred:

Traceback (most recent call last):
  File "main.py", line 10, in <module>
    data_ingestion.main()
  File "d:\text_summarizer\src\Text_Summarizer\pipeline\stage_01_data_ingestion.py", line 11, in main
    config = ConfigurationManager()
  File "d:\text_summarizer\src\Text_Summarizer\config\configuration.py", line 12, in __init__
    self.params=read_yaml(params_filepath)
  File "C:\Users\hp\anaconda3\envs\texts\lib\site-packages\ensure\main.py", line 849, in __call__
    return_val = self.f(*args, **kwargs)
  File "d:\text_summarizer\src\Text_Summarizer\utils\common.py", line 31, in read_yaml
    raise ValueError("yaml file is empty")
ValueError: yaml file is empty
[2024-06-25 17:58:18,235: INFO: main: >>>> stageData Ingestion Stage started<<<]
[2024-06-25 17:58:18,235: INFO: common: yaml file: config\config.yaml loaded successfully]
[2024-06-25 17:58:18,235: INFO: common: yaml file: params.yaml loaded successfully]
[2024-06-25 17:58:18,235: ERROR: main: yaml file is empty]
Traceback (most recent call last):
  File "d:\text_summarizer\src\Text_Summarizer\utils\common.py", line 29, in read_yaml
    return ConfigBox(content)
  File "box\box.py", line 259, in box.box.Box.__init__
box.exceptions.BoxValueError: First argument must be mapping or iterable

During handling of the above exception, another exception occurred:

Traceback (most recent call last):
  File "main.py", line 10, in <module>
    data_ingestion.main()
  File "d:\text_summarizer\src\Text_Summarizer\pipeline\stage_01_data_ingestion.py", line 11, in main
    config = ConfigurationManager()
  File "d:\text_summarizer\src\Text_Summarizer\config\configuration.py", line 12, in __init__
    self.params=read_yaml(params_filepath)
  File "C:\Users\hp\anaconda3\envs\texts\lib\site-packages\ensure\main.py", line 849, in __call__
    return_val = self.f(*args, **kwargs)
  File "d:\text_summarizer\src\Text_Summarizer\utils\common.py", line 31, in read_yaml
    raise ValueError("yaml file is empty")
ValueError: yaml file is empty
[2024-06-26 13:56:24,850: INFO: main: >>>> stageData Ingestion Stage started<<<]
[2024-06-26 13:56:24,850: INFO: common: yaml file: config\config.yaml loaded successfully]
[2024-06-26 13:56:24,850: INFO: common: yaml file: params.yaml loaded successfully]
[2024-06-26 13:56:24,850: ERROR: main: yaml file is empty]
Traceback (most recent call last):
  File "d:\text_summarizer\src\Text_Summarizer\utils\common.py", line 29, in read_yaml
    return ConfigBox(content)
  File "box\box.py", line 259, in box.box.Box.__init__
box.exceptions.BoxValueError: First argument must be mapping or iterable

During handling of the above exception, another exception occurred:

Traceback (most recent call last):
  File "main.py", line 10, in <module>
    data_ingestion.main()
  File "d:\text_summarizer\src\Text_Summarizer\pipeline\stage_01_data_ingestion.py", line 11, in main
    config = ConfigurationManager()
  File "d:\text_summarizer\src\Text_Summarizer\config\configuration.py", line 12, in __init__
    self.params=read_yaml(params_filepath)
  File "C:\Users\hp\anaconda3\envs\texts\lib\site-packages\ensure\main.py", line 849, in __call__
    return_val = self.f(*args, **kwargs)
  File "d:\text_summarizer\src\Text_Summarizer\utils\common.py", line 31, in read_yaml
    raise ValueError("yaml file is empty")
ValueError: yaml file is empty
[2024-06-26 13:59:11,794: INFO: main: >>>> stageData Ingestion Stage started<<<]
[2024-06-26 13:59:11,794: INFO: common: yaml file: config\config.yaml loaded successfully]
[2024-06-26 13:59:11,794: INFO: common: yaml file: params.yaml loaded successfully]
[2024-06-26 13:59:11,794: ERROR: main: yaml file is empty]
Traceback (most recent call last):
  File "d:\text_summarizer\src\Text_Summarizer\utils\common.py", line 30, in read_yaml
    return ConfigBox(content)
  File "box\box.py", line 259, in box.box.Box.__init__
box.exceptions.BoxValueError: First argument must be mapping or iterable

During handling of the above exception, another exception occurred:

Traceback (most recent call last):
  File "main.py", line 10, in <module>
    data_ingestion.main()
  File "d:\text_summarizer\src\Text_Summarizer\pipeline\stage_01_data_ingestion.py", line 11, in main
    config = ConfigurationManager()
  File "d:\text_summarizer\src\Text_Summarizer\config\configuration.py", line 12, in __init__
    self.params=read_yaml(params_filepath)
  File "C:\Users\hp\anaconda3\envs\texts\lib\site-packages\ensure\main.py", line 849, in __call__
    return_val = self.f(*args, **kwargs)
  File "d:\text_summarizer\src\Text_Summarizer\utils\common.py", line 32, in read_yaml
    raise ValueError("yaml file is empty")
ValueError: yaml file is empty
[2024-06-26 14:04:21,614: INFO: main: >>>> stageData Ingestion Stage started<<<]
[2024-06-26 14:04:21,614: INFO: common: yaml file: config\config.yaml loaded successfully]
[2024-06-26 14:04:21,622: INFO: common: yaml file: params.yaml loaded successfully]
[2024-06-26 14:04:21,622: ERROR: main: yaml file is empty]
Traceback (most recent call last):
  File "d:\text_summarizer\src\Text_Summarizer\utils\common.py", line 30, in read_yaml
    return ConfigBox(content)
  File "box\box.py", line 259, in box.box.Box.__init__
box.exceptions.BoxValueError: First argument must be mapping or iterable

During handling of the above exception, another exception occurred:

Traceback (most recent call last):
  File "main.py", line 10, in <module>
    data_ingestion.main()
  File "d:\text_summarizer\src\Text_Summarizer\pipeline\stage_01_data_ingestion.py", line 11, in main
    config = ConfigurationManager()
  File "d:\text_summarizer\src\Text_Summarizer\config\configuration.py", line 12, in __init__
    self.params=read_yaml(params_filepath)
  File "C:\Users\hp\anaconda3\envs\texts\lib\site-packages\ensure\main.py", line 849, in __call__
    return_val = self.f(*args, **kwargs)
  File "d:\text_summarizer\src\Text_Summarizer\utils\common.py", line 32, in read_yaml
    raise ValueError("yaml file is empty")
ValueError: yaml file is empty
[2024-06-28 13:59:10,063: INFO: main: >>>> stageData Ingestion Stage started<<<]
[2024-06-28 13:59:10,075: INFO: common: yaml file: config\config.yaml loaded successfully]
[2024-06-28 13:59:10,078: INFO: common: yaml file: params.yaml loaded successfully]
[2024-06-28 13:59:10,078: INFO: common: created directory at: artifacts]
[2024-06-28 13:59:10,078: INFO: common: created directory at: artifacts/data_ingestion]
[2024-06-28 13:59:10,082: ERROR: main: 'NoneType' object has no attribute 'local_data_file']
Traceback (most recent call last):
  File "main.py", line 10, in <module>
    data_ingestion.main()
  File "d:\text_summarizer\src\Text_Summarizer\pipeline\stage_01_data_ingestion.py", line 14, in main
    data_ingestion.download_file()
  File "d:\text_summarizer\src\Text_Summarizer\components\data_ingestion.py", line 16, in download_file
    if not os.path.exists(self.config.local_data_file):
AttributeError: 'NoneType' object has no attribute 'local_data_file'
[2024-06-28 14:09:23,345: INFO: main: >>>> stageData Ingestion Stage started<<<]
[2024-06-28 14:09:23,345: INFO: common: yaml file: config\config.yaml loaded successfully]
[2024-06-28 14:09:23,345: INFO: common: yaml file: params.yaml loaded successfully]
[2024-06-28 14:09:23,345: INFO: common: created directory at: artifacts]
[2024-06-28 14:09:23,345: INFO: common: created directory at: artifacts/data_ingestion]
[2024-06-28 14:09:23,345: ERROR: main: 'NoneType' object has no attribute 'local_data_file']
Traceback (most recent call last):
  File "main.py", line 10, in <module>
    data_ingestion.main()
  File "d:\text_summarizer\src\Text_Summarizer\pipeline\stage_01_data_ingestion.py", line 14, in main
    data_ingestion.download_file()
  File "d:\text_summarizer\src\Text_Summarizer\components\data_ingestion.py", line 16, in download_file
    if not os.path.exists(self.config.local_data_file):
AttributeError: 'NoneType' object has no attribute 'local_data_file'
[2024-06-28 14:17:55,875: INFO: main: >>>> stageData Ingestion Stage started<<<]
[2024-06-28 14:17:55,875: INFO: common: yaml file: config\config.yaml loaded successfully]
[2024-06-28 14:17:55,875: INFO: common: yaml file: params.yaml loaded successfully]
[2024-06-28 14:17:55,881: INFO: common: created directory at: artifacts]
[2024-06-28 14:17:55,881: INFO: common: created directory at: artifacts/data_ingestion]
[2024-06-28 14:17:58,962: INFO: data_ingestion: artifacts/data_ingestion/data.zip download! with following info: 
Connection: close
Content-Length: 7903594
Cache-Control: max-age=300
Content-Security-Policy: default-src 'none'; style-src 'unsafe-inline'; sandbox
Content-Type: application/zip
ETag: "dbc016a060da18070593b83afff580c9b300f0b6ea4147a7988433e04df246ca"
Strict-Transport-Security: max-age=31536000
X-Content-Type-Options: nosniff
X-Frame-Options: deny
X-XSS-Protection: 1; mode=block
X-GitHub-Request-Id: D551:57797:12D21B:173E45:667E6DD1
Accept-Ranges: bytes
Date: Fri, 28 Jun 2024 08:32:54 GMT
Via: 1.1 varnish
X-Served-By: cache-del21729-DEL
X-Cache: HIT
X-Cache-Hits: 0
X-Timer: S1719563574.222228,VS0,VE279
Vary: Authorization,Accept-Encoding,Origin
Access-Control-Allow-Origin: *
Cross-Origin-Resource-Policy: cross-origin
X-Fastly-Request-ID: f5af406029c4a0e41850937ffd012bf30e586d3c
Expires: Fri, 28 Jun 2024 08:37:54 GMT
Source-Age: 0

]
[2024-06-28 14:17:59,181: INFO: main: >>> stageData Ingestion Stage completed <<<<

====x]
